Workbook

Sheet Caza
D1: Total Semanal | E1: =SUM(E4:E106) -> 2038 | F1: =SUM(F4:F106) -> 104 | G1: =SUM(G4:G106) -> 1524 | H1: =SUM(H4:H106) -> 374 | I1: =SUM(I4:I106) -> 36 | J1: =SUM(J4:J106) -> 0 | K1: =SUM(K4:K106) -> 3718 | L1: =SUM(L4:L106) -> 14414 | M1: =SUM(M4:M106) -> 556
A3: Cuota | B3: Status | C3: IGG ID | D3: Nombre | E3: Total | F3: Total Mobs lvl 1 | G3: Total Mobs lvl 2 | H3: Total Mobs lvl 3 | I3: Total Mobs lvl 4 | J3: Total Mobs lvl 5 | K3: Puntos Nvl 2 | L3: Puntos Nvl 1 | M3: Debe | N3: Fecha Reporte
A4: =IF(ISERROR(VLOOKUP(C4,'Caza lvl 1'!A:A,1,0)),"5lvl2","5lvl1") -> 5lvl2 | B4: =_xlfn.IFS(A4 = "5lvl2",IF(K4>=35,"Cumplio", "No cumplio"),A4 = "5lvl1",IF(L4>= 35,"Cumplio","No cumplio")) -> Cumplio | C4: 416845218 | D4: Abraracurcix | E4: =SUM(F4:J4) -> 30 | F4: 0 | G4: 27 | H4: 3 | I4: 0 | J4: 0 | K4: =(H4*5)+(I4*9)+(J4*18)+G4 -> 42 | L4: =(G4*5)+(H4*15)+(I4*30)+(J4*70)+F4 -> 180 | M4: {=_xlfn.IFS(A4="5lvl2",IF(K4>=35,0,35-K4), A4="5lvl1",IF(L4>=35,0,35-L4))} -> 0 | N4: 01/06/2026 al 07/06/2026
A5: =IF(ISERROR(VLOOKUP(C5,'Caza lvl 1'!A:A,1,0)),"5lvl2","5lvl1") -> 5lvl2 | B5: =_xlfn.IFS(A5 = "5lvl2",IF(K5>=35,"Cumplio", "No cumplio"),A5 = "5lvl1",IF(L5>= 35,"Cumplio","No cumplio")) -> No cumplio | C5: 0 | D5: Adriana2791 | E5: =SUM(F5:J5) -> 2 | F5: 0 | G5: 2 | H5: 0 | I5: 0 | J5: 0 | K5: =(H5*5)+(I5*9)+(J5*18)+G5 -> 2 | L5: =(G5*5)+(H5*15)+(I5*30)+(J5*70)+F5 -> 10 | M5: {=_xlfn.IFS(A5="5lvl2",IF(K5>=35,0,35-K5), A5="5lvl1",IF(L5>=35,0,35-L5))} -> 33
A6: =IF(ISERROR(VLOOKUP(C6,'Caza lvl 1'!A:A,1,0)),"5lvl2","5lvl1") -> 5lvl2 | B6: =_xlfn.IFS(A6 = "5lvl2",IF(K6>=35,"Cumplio", "No cumplio"),A6 = "5lvl1",IF(L6>= 35,"Cumplio","No cumplio")) -> Cumplio | C6: 346561690 | D6: AGUIRRE1 | E6: =SUM(F6:J6) -> 14 | F6: 0 | G6: 3 | H6: 11 | I6: 0 | J6: 0 | K6: =(H6*5)+(I6*9)+(J6*18)+G6 -> 58 | L6: =(G6*5)+(H6*15)+(I6*30)+(J6*70)+F6 -> 180 | M6: {=_xlfn.IFS(A6="5lvl2",IF(K6>=35,0,35-K6), A6="5lvl1",IF(L6>=35,0,35-L6))} -> 0
A7: =IF(ISERROR(VLOOKUP(C7,'Caza lvl 1'!A:A,1,0)),"5lvl2","5lvl1") -> 5lvl2 | B7: =_xlfn.IFS(A7 = "5lvl2",IF(K7>=35,"Cumplio", "No cumplio"),A7 = "5lvl1",IF(L7>= 35,"Cumplio","No cumplio")) -> Cumplio | C7: 365438142 | D7: AGUIRRE1992 | E7: =SUM(F7:J7) -> 14 | F7: 0 | G7: 7 | H7: 7 | I7: 0 | J7: 0 | K7: =(H7*5)+(I7*9)+(J7*18)+G7 -> 42 | L7: =(G7*5)+(H7*15)+(I7*30)+(J7*70)+F7 -> 140 | M7: {=_xlfn.IFS(A7="5lvl2",IF(K7>=35,0,35-K7), A7="5lvl1",IF(L7>=35,0,35-L7))} -> 0
A8: =IF(ISERROR(VLOOKUP(C8,'Caza lvl 1'!A:A,1,0)),"5lvl2","5lvl1") -> 5lvl2 | B8: =_xlfn.IFS(A8 = "5lvl2",IF(K8>=35,"Cumplio", "No cumplio"),A8 = "5lvl1",IF(L8>= 35,"Cumplio","No cumplio")) -> No cumplio | C8: 0 | D8: Anonymous | E8: =SUM(F8:J8) -> 0 | F8: 0 | G8: 0 | H8: 0 | I8: 0 | J8: 0 | K8: =(H8*5)+(I8*9)+(J8*18)+G8 -> 0 | L8: =(G8*5)+(H8*15)+(I8*30)+(J8*70)+F8 -> 0 | M8: {=_xlfn.IFS(A8="5lvl2",IF(K8>=35,0,35-K8), A8="5lvl1",IF(L8>=35,0,35-L8))} -> 35
A9: =IF(ISERROR(VLOOKUP(C9,'Caza lvl 1'!A:A,1,0)),"5lvl2","5lvl1") -> 5lvl2 | B9: =_xlfn.IFS(A9 = "5lvl2",IF(K9>=35,"Cumplio", "No cumplio"),A9 = "5lvl1",IF(L9>= 35,"Cumplio","No cumplio")) -> Cumplio | C9: 326455645 | D9: Asterix I | E9: =SUM(F9:J9) -> 14 | F9: 0 | G9: 11 | H9: 0 | I9: 3 | J9: 0 | K9: =(H9*5)+(I9*9)+(J9*18)+G9 -> 38 | L9: =(G9*5)+(H9*15)+(I9*30)+(J9*70)+F9 -> 145 | M9: {=_xlfn.IFS(A9="5lvl2",IF(K9>=35,0,35-K9), A9="5lvl1",IF(L9>=35,0,35-L9))} -> 0
A10: =IF(ISERROR(VLOOKUP(C10,'Caza lvl 1'!A:A,1,0)),"5lvl2","5lvl1") -> 5lvl1 | B10: =_xlfn.IFS(A10 = "5lvl2",IF(K10>=35,"Cumplio", "No cumplio"),A10 = "5lvl1",IF(L10>= 35,"Cumplio","No cumplio")) -> Cumplio | C10: 2115871936 | D10: Atlas55555 | E10: =SUM(F10:J10) -> 23 | F10: 20 | G10: 3 | H10: 0 | I10: 0 | J10: 0 | K10: =(H10*5)+(I10*9)+(J10*18)+G10 -> 3 | L10: =(G10*5)+(H10*15)+(I10*30)+(J10*70)+F10 -> 35 | M10: {=_xlfn.IFS(A10="5lvl2",IF(K10>=35,0,35-K10), A10="5lvl1",IF(L10>=35,0,35-L10))} -> 0
A11: =IF(ISERROR(VLOOKUP(C11,'Caza lvl 1'!A:A,1,0)),"5lvl2","5lvl1") -> 5lvl1 | B11: =_xlfn.IFS(A11 = "5lvl2",IF(K11>=35,"Cumplio", "No cumplio"),A11 = "5lvl1",IF(L11>= 35,"Cumplio","No cumplio")) -> Cumplio | C11: 2024927090 | D11: Atlas7770 | E11: =SUM(F11:J11) -> 5 | F11: 0 | G11: 4 | H11: 1 | I11: 0 | J11: 0 | K11: =(H11*5)+(I11*9)+(J11*18)+G11 -> 9 | L11: =(G11*5)+(H11*15)+(I11*30)+(J11*70)+F11 -> 35 | M11: {=_xlfn.IFS(A11="5lvl2",IF(K11>=35,0,35-K11), A11="5lvl1",IF(L11>=35,0,35-L11))} -> 0
A12: =IF(ISERROR(VLOOKUP(C12,'Caza lvl 1'!A:A,1,0)),"5lvl2","5lvl1") -> 5lvl1 | B12: =_xlfn.IFS(A12 = "5lvl2",IF(K12>=35,"Cumplio", "No cumplio"),A12 = "5lvl1",IF(L12>= 35,"Cumplio","No cumplio")) -> Cumplio | C12: 1483867967 | D12: badboys1 | E12: =SUM(F12:J12) -> 8 | F12: 0 | G12: 7 | H12: 1 | I12: 0 | J12: 0 | K12: =(H12*5)+(I12*9)+(J12*18)+G12 -> 12 | L12: =(G12*5)+(H12*15)+(I12*30)+(J12*70)+F12 -> 50 | M12: {=_xlfn.IFS(A12="5lvl2",IF(K12>=35,0,35-K12), A12="5lvl1",IF(L12>=35,0,35-L12))} -> 0
A13: =IF(ISERROR(VLOOKUP(C13,'Caza lvl 1'!A:A,1,0)),"5lvl2","5lvl1") -> 5lvl2 | B13: =_xlfn.IFS(A13 = "5lvl2",IF(K13>=35,"Cumplio", "No cumplio"),A13 = "5lvl1",IF(L13>= 35,"Cumplio","No cumplio")) -> Cumplio | C13: 357402771 | D13: Barometrix | E13: =SUM(F13:J13) -> 23 | F13: 0 | G13: 21 | H13: 1 | I13: 1 | J13: 0 | K13: =(H13*5)+(I13*9)+(J13*18)+G13 -> 35 | L13: =(G13*5)+(H13*15)+(I13*30)+(J13*70)+F13 -> 150 | M13: {=_xlfn.IFS(A13="5lvl2",IF(K13>=35,0,35-K13), A13="5lvl1",IF(L13>=35,0,35-L13))} -> 0
A14: =IF(ISERROR(VLOOKUP(C14,'Caza lvl 1'!A:A,1,0)),"5lvl2","5lvl1") -> 5lvl2 | B14: =_xlfn.IFS(A14 = "5lvl2",IF(K14>=35,"Cumplio", "No cumplio"),A14 = "5lvl1",IF(L14>= 35,"Cumplio","No cumplio")) -> No cumplio | C14: 1041405085 | D14: BK Juanjo | E14: =SUM(F14:J14) -> 25 | F14: 0 | G14: 25 | H14: 0 | I14: 0 | J14: 0 | K14: =(H14*5)+(I14*9)+(J14*18)+G14 -> 25 | L14: =(G14*5)+(H14*15)+(I14*30)+(J14*70)+F14 -> 125 | M14: {=_xlfn.IFS(A14="5lvl2",IF(K14>=35,0,35-K14), A14="5lvl1",IF(L14>=35,0,35-L14))} -> 10
A15: =IF(ISERROR(VLOOKUP(C15,'Caza lvl 1'!A:A,1,0)),"5lvl2","5lvl1") -> 5lvl2 | B15: =_xlfn.IFS(A15 = "5lvl2",IF(K15>=35,"Cumplio", "No cumplio"),A15 = "5lvl1",IF(L15>= 35,"Cumplio","No cumplio")) -> Cumplio | C15: 527890484 | D15: Blurdomking | E15: =SUM(F15:J15) -> 61 | F15: 0 | G15: 54 | H15: 7 | I15: 0 | J15: 0 | K15: =(H15*5)+(I15*9)+(J15*18)+G15 -> 89 | L15: =(G15*5)+(H15*15)+(I15*30)+(J15*70)+F15 -> 375 | M15: {=_xlfn.IFS(A15="5lvl2",IF(K15>=35,0,35-K15), A15="5lvl1",IF(L15>=35,0,35-L15))} -> 0
A16: =IF(ISERROR(VLOOKUP(C16,'Caza lvl 1'!A:A,1,0)),"5lvl2","5lvl1") -> 5lvl2 | B16: =_xlfn.IFS(A16 = "5lvl2",IF(K16>=35,"Cumplio", "No cumplio"),A16 = "5lvl1",IF(L16>= 35,"Cumplio","No cumplio")) -> Cumplio | C16: 1036786251 | D16: cafecitofrio | E16: =SUM(F16:J16) -> 17 | F16: 0 | G16: 8 | H16: 9 | I16: 0 | J16: 0 | K16: =(H16*5)+(I16*9)+(J16*18)+G16 -> 53 | L16: =(G16*5)+(H16*15)+(I16*30)+(J16*70)+F16 -> 175 | M16: {=_xlfn.IFS(A16="5lvl2",IF(K16>=35,0,35-K16), A16="5lvl1",IF(L16>=35,0,35-L16))} -> 0
... A106: =IF(ISERROR(VLOOKUP(C106,'Caza lvl 1'!A:A,1,0)),"5lvl2","5lvl1") -> 5lvl2 | B106: =_xlfn.IFS(A106 = "5lvl2",IF(K106>=35,"Cumplio", "No cumplio"),A106 = "5lvl1",IF(L106>= 35,"Cumplio","No cumplio")) -> Cumplio | C106: 884346374 | D106: ZOOMBI3XX | E106: =SUM(F106:J106) -> 42 | F106: 0 | G106: 35 | H106: 6 | I106: 1 | J106: 0 | K106: =(H106*5)+(I106*9)+(J106*18)+G106 -> 74 | L106: =(G106*5)+(H106*15)+(I106*30)+(J106*70)+F106 -> 295 | M106: {=_xlfn.IFS(A106="5lvl2",IF(K106>=35,0,35-K106), A106="5lvl1",IF(L106>=35,0,35-L106))} -> 0

Sheet Caza lvl 1
A1: IGGID | B1: NOMBRE
A2: 1367372226 | B2: XxtatuxX
A3: 1940642101 | B3: tetona
A4: 2057192192 | B4: NotLife2
A5: 2024927090 | B5: Atlas7770
A6: 2060348531 | B6: Hotspot 2
A7: 1338792213 | B7: El Guti26
A8: 677690297 | B8: FOODmil
A9: 600359996 | B9: lZvG Warasl
A10: 2115871936 | B10: Atlas55555
A11: 1390607562 | B11: criatura02
A12: 1931591455 | B12: XXGAELICOXX
A13: 1211883975 | B13: Online 16
... A17: 1067470462 | B17: OoChispitaoO

Sheet Ranking Evento
A1: # | B1: IGG ID | C1: Nombre | D1: 07/06/2026 | E1: Columna4 | F1: Columna3 | G1: Columna2 | H1: Columna1 | I1: Total | K1: Mes del Reporte
A2: 1 | B2: 884346374 | C2: ZOOMBI3XX | D2: =IFERROR(VLOOKUP(B2,Caza!C:K,9,0), 0) -> 74 | I2: =SUM(D2:H2) -> 74 | K2: JUNIO
A3: 2 | B3: 640955210 | C3: Valentin | D3: =IFERROR(VLOOKUP(B3,Caza!C:K,9,0), 0) -> 39 | I3: =SUM(D3:H3) -> 39
A4: 3 | B4: 1023770253 | C4: K4K4SHI009 | D4: =IFERROR(VLOOKUP(B4,Caza!C:K,9,0), 0) -> 82 | I4: =SUM(D4:H4) -> 82
A5: 4 | B5: 559847999 | C5: SoNy5 | D5: =IFERROR(VLOOKUP(B5,Caza!C:K,9,0), 0) -> 39 | I5: =SUM(D5:H5) -> 39
A6: 5 | B6: 500920417 | C6: No Soy Bro | D6: =IFERROR(VLOOKUP(B6,Caza!C:K,9,0), 0) -> 65 | I6: =SUM(D6:H6) -> 65
A7: 6 | B7: 1346964807 | C7: GokuBlack25 | D7: =IFERROR(VLOOKUP(B7,Caza!C:K,9,0), 0) -> 42 | I7: =SUM(D7:H7) -> 42
A8: 7 | B8: 471968668 | C8: David051190 | D8: =IFERROR(VLOOKUP(B8,Caza!C:K,9,0), 0) -> 54 | I8: =SUM(D8:H8) -> 54
A9: 8 | B9: 710619616 | C9: Vampyro3xxx | D9: =IFERROR(VLOOKUP(B9,Caza!C:K,9,0), 0) -> 9 | I9: =SUM(D9:H9) -> 9
A10: 9 | B10: 689257712 | C10: Juanjojjp | D10: =IFERROR(VLOOKUP(B10,Caza!C:K,9,0), 0) -> 91 | I10: =SUM(D10:H10) -> 91
A11: 10 | B11: 516441517 | C11: I GNACIO | D11: =IFERROR(VLOOKUP(B11,Caza!C:K,9,0), 0) -> 59 | I11: =SUM(D11:H11) -> 59
A12: 11 | B12: 658843231 | C12: LifeToxic | D12: =IFERROR(VLOOKUP(B12,Caza!C:K,9,0), 0) -> 77 | I12: =SUM(D12:H12) -> 77
A13: 12 | B13: 424972261 | C13: VALEP | D13: =IFERROR(VLOOKUP(B13,Caza!C:K,9,0), 0) -> 60 | I13: =SUM(D13:H13) -> 60
A14: 13 | B14: 1092680272 | C14: ins4n3 TH | D14: =IFERROR(VLOOKUP(B14,Caza!C:K,9,0), 0) -> 66 | I14: =SUM(D14:H14) -> 66
... A101: 100 | B101: 1367372226 | C101: xtatux12 | D101: =IFERROR(VLOOKUP(B101,Caza!C:K,9,0), 0) -> 0 | I101: =SUM(D101:H101) -> 0
A102: 101 | D102: =IFERROR(VLOOKUP(B102,Caza!C:K,9,0), 0) -> 2 | I102: =SUM(D102:H102) -> 2
A103: 104 | D103: =IFERROR(VLOOKUP(B103,Caza!C:K,9,0), 0) -> 2 | I103: =SUM(D103:H103) -> 2
A104: 105 | D104: =IFERROR(VLOOKUP(B104,Caza!C:K,9,0), 0) -> 2 | I104: =SUM(D104:H104) -> 2
A105: 106 | D105: =IFERROR(VLOOKUP(B105,Caza!C:K,9,0), 0) -> 2 | I105: =SUM(D105:H105) -> 2
A106: 107 | D106: =IFERROR(VLOOKUP(B106,Caza!C:K,9,0), 0) -> 2 | I106: =SUM(D106:H106) -> 2
A107: 108 | D107: =IFERROR(VLOOKUP(B107,Caza!C:K,9,0), 0) -> 2 | I107: =SUM(D107:H107) -> 2
A108: 109 | D108: =IFERROR(VLOOKUP(B108,Caza!C:K,9,0), 0) -> 2 | I108: =SUM(D108:H108) -> 2
A109: 110 | D109: =IFERROR(VLOOKUP(B109,Caza!C:K,9,0), 0) -> 2 | I109: =SUM(D109:H109) -> 2
A110: 111 | D110: =IFERROR(VLOOKUP(B110,Caza!C:K,9,0), 0) -> 2 | I110: =SUM(D110:H110) -> 2
A111: 112 | D111: =IFERROR(VLOOKUP(B111,Caza!C:K,9,0), 0) -> 2 | I111: =SUM(D111:H111) -> 2
A112: 113 | D112: =IFERROR(VLOOKUP(B112,Caza!C:K,9,0), 0) -> 2 | I112: =SUM(D112:H112) -> 2
A113: 114 | D113: =IFERROR(VLOOKUP(B113,Caza!C:K,9,0), 0) -> 2 | I113: =SUM(D113:H113) -> 2
... A115: 116 | D115: =IFERROR(VLOOKUP(B115,Caza!C:K,9,0), 0) -> 2 | I115: =SUM(D115:H115) -> 2
D116: =IFERROR(VLOOKUP(B116,Caza!C:K,9,0), 0) -> 2 | I116: =SUM(D116:H116) -> 2

Sheet FDG
A1: Nombre | B1: Misiones completadas | C1: Misiones tomadas | D1: Puntos | F1: Fecha de Reporte
A2: X BAILEN X | B2: 16 | C2: 16 | D2: 4902 | F2: 25/05/2026 al 31/05/2026
A3: Nydan D | B3: 16 | C3: 16 | D3: 4671
A4: Megadiablo | B4: 16 | C4: 16 | D4: 4383
A5: Vampyro3xxx | B5: 16 | C5: 16 | D5: 4367
A6: GokuBlack25 | B6: 16 | C6: 16 | D6: 4234
A7: Atlas55555 | B7: 16 | C7: 16 | D7: 4182
A8: Inng3nN | B8: 16 | C8: 16 | D8: 4141
A9: JonyG2013 | B9: 16 | C9: 16 | D9: 4133
A10: Notlife 1 | B10: 16 | C10: 16 | D10: 4092
A11: Gastly237 | B11: 16 | C11: 16 | D11: 4079
A12: Th3BigB0ss | B12: 16 | C12: 16 | D12: 4066
A13: Maxi D | B13: 16 | C13: 16 | D13: 4060
A14: Barometrix | B14: 16 | C14: 16 | D14: 4033
... A95: Blurdomking | B95: 0 | C95: 0 | D95: 0

Sheet Avisos
A1: Cuota Diaria | B1: Status | C1: IGG ID | D1: Nombre | E1: Total Semanal | F1: Mob1 | G1: Mob2 | H1: Mob3 | I1: Mob4 | J1: Mob5 | K1: Puntos Nvl 2 | L1: Puntos Nvl 1 | M1: Debe | N1: Numero | O1: Puntos x cumplir | P1: Semana anterior | Q1: 46152 | R1: 46159 | S1: 46166
A2: 5lvl2 | B2: No cumplio | C2: 735092980 | D2: Gengar237 | E2: 5 | F2: 2 | G2: 2 | H2: 1 | I2: 0 | J2: 0 | K2: 7 | L2: 27 | M2: 28 | N2: =IFERROR(VLOOKUP(C2,Numeros!A:C,3,0),584121633097) -> 5212211427683 | O2: =SUM(M2,Q2,R2,S2)+35 -> 63 | P2: =COUNTIF(#REF!, C2)>0 -> #REF! | Q2: 0 | R2: 0 | S2: 0
A3: 5lvl2 | B3: No cumplio | C3: 663429510 | D3: Megadiablo | E3: 19 | F3: 0 | G3: 16 | H3: 3 | I3: 0 | J3: 0 | K3: 31 | L3: 125 | M3: 4 | N3: =IFERROR(VLOOKUP(C3,Numeros!A:C,3,0),584121633097) -> 5214251085901 | O3: =SUM(M3,Q3,R3,S3)+35 -> 39 | P3: =COUNTIF(#REF!, C3)>0 -> #REF! | Q3: 0 | R3: 0 | S3: 0
A4: 5lvl2 | B4: No cumplio | C4: 1040811175 | D4: SantiagoTb | E4: 10 | F4: 0 | G4: 4 | H4: 6 | I4: 0 | J4: 0 | K4: 34 | L4: 110 | M4: 1 | N4: =IFERROR(VLOOKUP(C4,Numeros!A:C,3,0),584121633097) -> 5219611812448 | O4: =SUM(M4,Q4,R4,S4)+35 -> 36 | P4: =COUNTIF(#REF!, C4)>0 -> #REF! | Q4: 0 | R4: 0 | S4: 0

Sheet Numeros
A1: IGG ID | B1: Nombre | C1: Numero
A2: 416845218 | B2: =VLOOKUP(Tabla6[[#This Row],[IGG ID]],Caza!C:D,2,0) -> Abraracurcix | C2: 5491159089014
A3: 346561690 | B3: =VLOOKUP(Tabla6[[#This Row],[IGG ID]],Caza!C:D,2,0) -> AGUIRRE1 | C3: 5493417036998
A4: 365438142 | B4: =VLOOKUP(Tabla6[[#This Row],[IGG ID]],Caza!C:D,2,0) -> AGUIRRE1992 | C4: 5493417036998
A5: 673621517 | B5: =VLOOKUP(Tabla6[[#This Row],[IGG ID]],Caza!C:D,2,0) -> #N/A
A6: 0 | B6: =VLOOKUP(Tabla6[[#This Row],[IGG ID]],Caza!C:D,2,0) -> Adriana2791
A7: 326455645 | B7: =VLOOKUP(Tabla6[[#This Row],[IGG ID]],Caza!C:D,2,0) -> Asterix I | C7: 5491159089014
A8: 2115871936 | B8: =VLOOKUP(Tabla6[[#This Row],[IGG ID]],Caza!C:D,2,0) -> Atlas55555 | C8: 584121633097
A9: 2024927090 | B9: =VLOOKUP(Tabla6[[#This Row],[IGG ID]],Caza!C:D,2,0) -> Atlas7770 | C9: 584121633097
A10: 1483867967 | B10: =VLOOKUP(Tabla6[[#This Row],[IGG ID]],Caza!C:D,2,0) -> badboys1 | C10: 556596113286
A11: 625607335 | B11: =VLOOKUP(Tabla6[[#This Row],[IGG ID]],Caza!C:D,2,0) -> Valkiria4xK | C11: 556596113286
A12: 357402771 | B12: =VLOOKUP(Tabla6[[#This Row],[IGG ID]],Caza!C:D,2,0) -> Barometrix | C12: 5491159089014
A13: 1041405085 | B13: =VLOOKUP(Tabla6[[#This Row],[IGG ID]],Caza!C:D,2,0) -> BK Juanjo | C13: 573142905763
A14: 554156976 | B14: =VLOOKUP(Tabla6[[#This Row],[IGG ID]],Caza!C:D,2,0) -> #N/A
A15: 527890484 | B15: =VLOOKUP(Tabla6[[#This Row],[IGG ID]],Caza!C:D,2,0) -> Blurdomking
A16: 1036786251 | B16: =VLOOKUP(Tabla6[[#This Row],[IGG ID]],Caza!C:D,2,0) -> cafecitofrio | C16: 56997784905
A17: 1922616643 | B17: =VLOOKUP(Tabla6[[#This Row],[IGG ID]],Caza!C:D,2,0) -> #N/A
A18: 747071768 | B18: =VLOOKUP(Tabla6[[#This Row],[IGG ID]],Caza!C:D,2,0) -> CHACHO 78 | C18: 34618068649
A19: 648763948 | B19: =VLOOKUP(Tabla6[[#This Row],[IGG ID]],Caza!C:D,2,0) -> chinita241
A20: 611721390 | B20: =VLOOKUP(Tabla6[[#This Row],[IGG ID]],Caza!C:D,2,0) -> CrakSoder25 | C20: 5215538901631
A21: 881905775 | B21: =VLOOKUP(Tabla6[[#This Row],[IGG ID]],Caza!C:D,2,0) -> DANTEE666
A22: 471968668 | B22: =VLOOKUP(Tabla6[[#This Row],[IGG ID]],Caza!C:D,2,0) -> David051190 | C22: 5493815620526
A23: 866932727 | B23: =VLOOKUP(Tabla6[[#This Row],[IGG ID]],Caza!C:D,2,0) -> #N/A | C23: 50575406105
A24: 648809825 | B24: =VLOOKUP(Tabla6[[#This Row],[IGG ID]],Caza!C:D,2,0) -> El YuVe
A25: 412543735 | B25: =VLOOKUP(Tabla6[[#This Row],[IGG ID]],Caza!C:D,2,0) -> ELFOSFO | C25: 5214495437706
A26: 723725687 | B26: =VLOOKUP(Tabla6[[#This Row],[IGG ID]],Caza!C:D,2,0) -> FALCON221 | C26: 34615730725
A27: 1698596813 | B27: =VLOOKUP(Tabla6[[#This Row],[IGG ID]],Caza!C:D,2,0) -> Gastly237 | C27: 5212211427683
A28: 735092980 | B28: =VLOOKUP(Tabla6[[#This Row],[IGG ID]],Caza!C:D,2,0) -> Gengar237 | C28: 5212211427683
A29: 1346964807 | B29: =VLOOKUP(Tabla6[[#This Row],[IGG ID]],Caza!C:D,2,0) -> GokuBlack25 | C29: 584129619123
A30: 1529804845 | B30: =VLOOKUP(Tabla6[[#This Row],[IGG ID]],Caza!C:D,2,0) -> GokuBlack26 | C30: 584129619123
A31: 817775064 | B31: =VLOOKUP(Tabla6[[#This Row],[IGG ID]],Caza!C:D,2,0) -> Hades 04
A32: 2060348531 | B32: =VLOOKUP(Tabla6[[#This Row],[IGG ID]],Caza!C:D,2,0) -> Hotspot 2 | C32: 584121633097
A33: 516441517 | B33: =VLOOKUP(Tabla6[[#This Row],[IGG ID]],Caza!C:D,2,0) -> I GNACIO
A34: 1041170254 | B34: =VLOOKUP(Tabla6[[#This Row],[IGG ID]],Caza!C:D,2,0) -> il pegaso | C34: 5215525003448
A35: 334846462 | B35: =VLOOKUP(Tabla6[[#This Row],[IGG ID]],Caza!C:D,2,0) -> Inng3nN | C35: 5214776551136
A36: 1092680272 | B36: =VLOOKUP(Tabla6[[#This Row],[IGG ID]],Caza!C:D,2,0) -> ins4n3 TH | C36: 584162672027
A37: 582104628 | B37: =VLOOKUP(Tabla6[[#This Row],[IGG ID]],Caza!C:D,2,0) -> JonyG2013 | C37: 5493815620526
A38: 689257712 | B38: =VLOOKUP(Tabla6[[#This Row],[IGG ID]],Caza!C:D,2,0) -> Juanjojjp | C38: 573142905763
A39: 1023770253 | B39: =VLOOKUP(Tabla6[[#This Row],[IGG ID]],Caza!C:D,2,0) -> K4K4SHI009 | C39: 584242029084
A40: 1041184896 | B40: =VLOOKUP(Tabla6[[#This Row],[IGG ID]],Caza!C:D,2,0) -> KeoIII1
...
