Workbook

Sheet Stats
A1: Cuota | B1: Status | C1: IGG ID | D1: Nombre | E1: Total Semanal | F1: Total Mobs lvl 1 | G1: Total Mobs lvl 2 | H1: Total Mobs lvl 3 | I1: Total Mobs lvl 4 | J1: Total Mobs lvl 5 | K1: Puntos Nvl 2 | L1: Puntos Nvl 1 | M1: Fecha de Reporte
A2: 5lvl2 | B2: Cumplio | C2: 416845218 | D2: Abraracurcix | E2: 12 | F2: 0 | G2: 8 | H2: 2 | I2: 2 | J2: 0 | K2: 36 | L2: 130 | M2: 25/05/2026 al 31/05/2026
A3: 5lvl2 | B3: Cumplio | C3: 346561690 | D3: AGUIRRE1 | E3: 21 | F3: 3 | G3: 12 | H3: 6 | I3: 0 | J3: 0 | K3: 42 | L3: 153
A4: 5lvl2 | B4: Cumplio | C4: 365438142 | D4: AGUIRRE1992 | E4: 19 | F4: 0 | G4: 13 | H4: 6 | I4: 0 | J4: 0 | K4: 43 | L4: 155
A5: 5lvl2 | B5: No cumplio | C5: 673621517 | D5: Andres HS4 | E5: 3 | F5: 0 | G5: 2 | H5: 1 | I5: 0 | J5: 0 | K5: 7 | L5: 25
A6: 5lvl2 | B6: No cumplio | C6: 0 | D6: Anonymous | E6: 0 | F6: 0 | G6: 0 | H6: 0 | I6: 0 | J6: 0 | K6: 0 | L6: 0
A7: 5lvl2 | B7: Cumplio | C7: 326455645 | D7: Asterix I | E7: 35 | F7: 0 | G7: 35 | H7: 0 | I7: 0 | J7: 0 | K7: 35 | L7: 175
A8: 5lvl1 | B8: Cumplio | C8: 2115871936 | D8: Atlas55555 | E8: 15 | F8: 10 | G8: 5 | H8: 0 | I8: 0 | J8: 0 | K8: 5 | L8: 35
A9: 5lvl1 | B9: Cumplio | C9: 2024927090 | D9: Atlas7770 | E9: 7 | F9: 0 | G9: 7 | H9: 0 | I9: 0 | J9: 0 | K9: 7 | L9: 35
A10: 5lvl1 | B10: Cumplio | C10: 1483867967 | D10: badboys1 | E10: 7 | F10: 0 | G10: 7 | H10: 0 | I10: 0 | J10: 0 | K10: 7 | L10: 35
A11: 5lvl2 | B11: Cumplio | C11: 625607335 | D11: BadBoys4k | E11: 20 | F11: 0 | G11: 15 | H11: 1 | I11: 3 | J11: 1 | K11: 65 | L11: 250
A12: 5lvl2 | B12: Cumplio | C12: 357402771 | D12: Barometrix | E12: 15 | F12: 0 | G12: 12 | H12: 1 | I12: 2 | J12: 0 | K12: 35 | L12: 135
A13: 5lvl2 | B13: Cumplio | C13: 1041405085 | D13: BK Juanjo | E13: 27 | F13: 0 | G13: 25 | H13: 2 | I13: 0 | J13: 0 | K13: 35 | L13: 155
A14: 5lvl2 | B14: No cumplio | C14: 554156976 | D14: Blackslayer5 | E14: 1 | F14: 0 | G14: 0 | H14: 1 | I14: 0 | J14: 0 | K14: 5 | L14: 15
... A101: 5lvl2 | B101: Cumplio | C101: 884346374 | D101: ZOOMBI3XX | E101: 38 | F101: 0 | G101: 36 | H101: 0 | I101: 0 | J101: 2 | K101: 72 | L101: 320

Sheet Top 10
A1: # | B1: Nombre | C1: Total | D1: Puntos | E1: Fecha Reporte
A2: 1 | B2: Abraracurcix | C2: 12 | D2: 36 | E2: 25/05/2026 al 31/05/2026
A3: 2 | B3: AGUIRRE1 | C3: 21 | D3: 42
A4: 3 | B4: AGUIRRE1992 | C4: 19 | D4: 43
A5: 4 | B5: Andres HS4 | C5: 3 | D5: 7
A6: 5 | B6: Anonymous | C6: 0 | D6: 0
A7: 6 | B7: Asterix I | C7: 35 | D7: 35
A8: 7 | B8: Atlas55555 | C8: 15 | D8: 5
A9: 8 | B9: Atlas7770 | C9: 7 | D9: 7
A10: 9 | B10: badboys1 | C10: 7 | D10: 7
A11: 10 | B11: BadBoys4k | C11: 20 | D11: 65
A12: 11 | B12: Barometrix | C12: 15 | D12: 35
A13: 12 | B13: BK Juanjo | C13: 27 | D13: 35
A14: 13 | B14: Blackslayer5 | C14: 1 | D14: 5
... A101: 100 | B101: ZOOMBI3XX | C101: 38 | D101: 72
A102: 101
A103: 102
A104: 103
A105: 104
A106: 105
A107: 106
A108: 107
A109: 108
A110: 109
A111: 110
A112: 111
A113: 112
... A125: 124

Sheet Caza
A1: Cuota Diaria | B1: Status | C1: IGG ID | D1: Nombre | E1: Total Semanal | F1: Total Mobs lvl 1 | G1: Total Mobs lvl 2 | H1: Total Mobs lvl 3 | I1: Total Mobs lvl 4 | J1: Total Mobs lvl 5 | M1: 25/05/2026 al 31/05/2026
D3: Total | E3: =SUM(E5:E104) -> 2401 | F3: =SUM(F5:F104) -> 136 | G3: =SUM(G5:G104) -> 1930 | H3: =SUM(H5:H104) -> 282 | I3: =SUM(I5:I104) -> 41 | J3: =SUM(J5:J104) -> 12
K4: Puntos Nvl 2 | L4: Puntos Nvl 1 | M4: Debe/No debe
A5: =IF(ISERROR(VLOOKUP(C5,'Caza lvl 1'!A:A,1,0)),"5lvl2","5lvl1") -> 5lvl2 | B5: =_xlfn.IFS(A5 = "5lvl2",IF(K5>=35,"Cumplio", "No cumplio"),A5 = "5lvl1",IF(L5>= 35,"Cumplio","No cumplio")) -> Cumplio | C5: 416845218 | D5: Abraracurcix | E5: =SUM(F5:J5) -> 12 | F5: 0 | G5: 8 | H5: 2 | I5: 2 | J5: 0 | K5: =(H5*5)+(I5*9)+(J5*18)+G5 -> 36 | L5: =(G5*5)+(H5*15)+(I5*30)+(J5*70)+F5 -> 130 | M5: {=_xlfn.IFS(A5="5lvl2",IF(K5>=35,"No debe",35-K5), A5="5lvl1",IF(L5>=35,"No debe",35-L5))} -> No debe
A6: =IF(ISERROR(VLOOKUP(C6,'Caza lvl 1'!A:A,1,0)),"5lvl2","5lvl1") -> 5lvl2 | B6: =_xlfn.IFS(A6 = "5lvl2",IF(K6>=35,"Cumplio", "No cumplio"),A6 = "5lvl1",IF(L6>= 35,"Cumplio","No cumplio")) -> Cumplio | C6: 346561690 | D6: AGUIRRE1 | E6: =SUM(F6:J6) -> 21 | F6: 3 | G6: 12 | H6: 6 | I6: 0 | J6: 0 | K6: =(H6*5)+(I6*9)+(J6*18)+G6 -> 42 | L6: =(G6*5)+(H6*15)+(I6*30)+(J6*70)+F6 -> 153 | M6: {=_xlfn.IFS(A6="5lvl2",IF(K6>=35,"No debe",35-K6), A6="5lvl1",IF(L6>=35,"No debe",35-L6))} -> No debe
A7: =IF(ISERROR(VLOOKUP(C7,'Caza lvl 1'!A:A,1,0)),"5lvl2","5lvl1") -> 5lvl2 | B7: =_xlfn.IFS(A7 = "5lvl2",IF(K7>=35,"Cumplio", "No cumplio"),A7 = "5lvl1",IF(L7>= 35,"Cumplio","No cumplio")) -> Cumplio | C7: 365438142 | D7: AGUIRRE1992 | E7: =SUM(F7:J7) -> 19 | F7: 0 | G7: 13 | H7: 6 | I7: 0 | J7: 0 | K7: =(H7*5)+(I7*9)+(J7*18)+G7 -> 43 | L7: =(G7*5)+(H7*15)+(I7*30)+(J7*70)+F7 -> 155 | M7: {=_xlfn.IFS(A7="5lvl2",IF(K7>=35,"No debe",35-K7), A7="5lvl1",IF(L7>=35,"No debe",35-L7))} -> No debe
A8: =IF(ISERROR(VLOOKUP(C8,'Caza lvl 1'!A:A,1,0)),"5lvl2","5lvl1") -> 5lvl2 | B8: =_xlfn.IFS(A8 = "5lvl2",IF(K8>=35,"Cumplio", "No cumplio"),A8 = "5lvl1",IF(L8>= 35,"Cumplio","No cumplio")) -> No cumplio | C8: 673621517 | D8: Andres HS4 | E8: =SUM(F8:J8) -> 3 | F8: 0 | G8: 2 | H8: 1 | I8: 0 | J8: 0 | K8: =(H8*5)+(I8*9)+(J8*18)+G8 -> 7 | L8: =(G8*5)+(H8*15)+(I8*30)+(J8*70)+F8 -> 25 | M8: {=_xlfn.IFS(A8="5lvl2",IF(K8>=35,"No debe",35-K8), A8="5lvl1",IF(L8>=35,"No debe",35-L8))} -> 28
A9: =IF(ISERROR(VLOOKUP(C9,'Caza lvl 1'!A:A,1,0)),"5lvl2","5lvl1") -> 5lvl2 | B9: =_xlfn.IFS(A9 = "5lvl2",IF(K9>=35,"Cumplio", "No cumplio"),A9 = "5lvl1",IF(L9>= 35,"Cumplio","No cumplio")) -> No cumplio | C9: 0 | D9: Anonymous | E9: =SUM(F9:J9) -> 0 | F9: 0 | G9: 0 | H9: 0 | I9: 0 | J9: 0 | K9: =(H9*5)+(I9*9)+(J9*18)+G9 -> 0 | L9: =(G9*5)+(H9*15)+(I9*30)+(J9*70)+F9 -> 0 | M9: {=_xlfn.IFS(A9="5lvl2",IF(K9>=35,"No debe",35-K9), A9="5lvl1",IF(L9>=35,"No debe",35-L9))} -> 35
A10: =IF(ISERROR(VLOOKUP(C10,'Caza lvl 1'!A:A,1,0)),"5lvl2","5lvl1") -> 5lvl2 | B10: =_xlfn.IFS(A10 = "5lvl2",IF(K10>=35,"Cumplio", "No cumplio"),A10 = "5lvl1",IF(L10>= 35,"Cumplio","No cumplio")) -> Cumplio | C10: 326455645 | D10: Asterix I | E10: =SUM(F10:J10) -> 35 | F10: 0 | G10: 35 | H10: 0 | I10: 0 | J10: 0 | K10: =(H10*5)+(I10*9)+(J10*18)+G10 -> 35 | L10: =(G10*5)+(H10*15)+(I10*30)+(J10*70)+F10 -> 175 | M10: {=_xlfn.IFS(A10="5lvl2",IF(K10>=35,"No debe",35-K10), A10="5lvl1",IF(L10>=35,"No debe",35-L10))} -> No debe
A11: =IF(ISERROR(VLOOKUP(C11,'Caza lvl 1'!A:A,1,0)),"5lvl2","5lvl1") -> 5lvl1 | B11: =_xlfn.IFS(A11 = "5lvl2",IF(K11>=35,"Cumplio", "No cumplio"),A11 = "5lvl1",IF(L11>= 35,"Cumplio","No cumplio")) -> Cumplio | C11: 2115871936 | D11: Atlas55555 | E11: =SUM(F11:J11) -> 15 | F11: 10 | G11: 5 | H11: 0 | I11: 0 | J11: 0 | K11: =(H11*5)+(I11*9)+(J11*18)+G11 -> 5 | L11: =(G11*5)+(H11*15)+(I11*30)+(J11*70)+F11 -> 35 | M11: {=_xlfn.IFS(A11="5lvl2",IF(K11>=35,"No debe",35-K11), A11="5lvl1",IF(L11>=35,"No debe",35-L11))} -> No debe
A12: =IF(ISERROR(VLOOKUP(C12,'Caza lvl 1'!A:A,1,0)),"5lvl2","5lvl1") -> 5lvl1 | B12: =_xlfn.IFS(A12 = "5lvl2",IF(K12>=35,"Cumplio", "No cumplio"),A12 = "5lvl1",IF(L12>= 35,"Cumplio","No cumplio")) -> Cumplio | C12: 2024927090 | D12: Atlas7770 | E12: =SUM(F12:J12) -> 7 | F12: 0 | G12: 7 | H12: 0 | I12: 0 | J12: 0 | K12: =(H12*5)+(I12*9)+(J12*18)+G12 -> 7 | L12: =(G12*5)+(H12*15)+(I12*30)+(J12*70)+F12 -> 35 | M12: {=_xlfn.IFS(A12="5lvl2",IF(K12>=35,"No debe",35-K12), A12="5lvl1",IF(L12>=35,"No debe",35-L12))} -> No debe
A13: =IF(ISERROR(VLOOKUP(C13,'Caza lvl 1'!A:A,1,0)),"5lvl2","5lvl1") -> 5lvl1 | B13: =_xlfn.IFS(A13 = "5lvl2",IF(K13>=35,"Cumplio", "No cumplio"),A13 = "5lvl1",IF(L13>= 35,"Cumplio","No cumplio")) -> Cumplio | C13: 1483867967 | D13: badboys1 | E13: =SUM(F13:J13) -> 7 | F13: 0 | G13: 7 | H13: 0 | I13: 0 | J13: 0 | K13: =(H13*5)+(I13*9)+(J13*18)+G13 -> 7 | L13: =(G13*5)+(H13*15)+(I13*30)+(J13*70)+F13 -> 35 | M13: {=_xlfn.IFS(A13="5lvl2",IF(K13>=35,"No debe",35-K13), A13="5lvl1",IF(L13>=35,"No debe",35-L13))} -> No debe
A14: =IF(ISERROR(VLOOKUP(C14,'Caza lvl 1'!A:A,1,0)),"5lvl2","5lvl1") -> 5lvl2 | B14: =_xlfn.IFS(A14 = "5lvl2",IF(K14>=35,"Cumplio", "No cumplio"),A14 = "5lvl1",IF(L14>= 35,"Cumplio","No cumplio")) -> Cumplio | C14: 625607335 | D14: BadBoys4k | E14: =SUM(F14:J14) -> 20 | F14: 0 | G14: 15 | H14: 1 | I14: 3 | J14: 1 | K14: =(H14*5)+(I14*9)+(J14*18)+G14 -> 65 | L14: =(G14*5)+(H14*15)+(I14*30)+(J14*70)+F14 -> 250 | M14: {=_xlfn.IFS(A14="5lvl2",IF(K14>=35,"No debe",35-K14), A14="5lvl1",IF(L14>=35,"No debe",35-L14))} -> No debe
A15: =IF(ISERROR(VLOOKUP(C15,'Caza lvl 1'!A:A,1,0)),"5lvl2","5lvl1") -> 5lvl2 | B15: =_xlfn.IFS(A15 = "5lvl2",IF(K15>=35,"Cumplio", "No cumplio"),A15 = "5lvl1",IF(L15>= 35,"Cumplio","No cumplio")) -> Cumplio | C15: 357402771 | D15: Barometrix | E15: =SUM(F15:J15) -> 15 | F15: 0 | G15: 12 | H15: 1 | I15: 2 | J15: 0 | K15: =(H15*5)+(I15*9)+(J15*18)+G15 -> 35 | L15: =(G15*5)+(H15*15)+(I15*30)+(J15*70)+F15 -> 135 | M15: {=_xlfn.IFS(A15="5lvl2",IF(K15>=35,"No debe",35-K15), A15="5lvl1",IF(L15>=35,"No debe",35-L15))} -> No debe
A16: =IF(ISERROR(VLOOKUP(C16,'Caza lvl 1'!A:A,1,0)),"5lvl2","5lvl1") -> 5lvl2 | B16: =_xlfn.IFS(A16 = "5lvl2",IF(K16>=35,"Cumplio", "No cumplio"),A16 = "5lvl1",IF(L16>= 35,"Cumplio","No cumplio")) -> Cumplio | C16: 1041405085 | D16: BK Juanjo | E16: =SUM(F16:J16) -> 27 | F16: 0 | G16: 25 | H16: 2 | I16: 0 | J16: 0 | K16: =(H16*5)+(I16*9)+(J16*18)+G16 -> 35 | L16: =(G16*5)+(H16*15)+(I16*30)+(J16*70)+F16 -> 155 | M16: {=_xlfn.IFS(A16="5lvl2",IF(K16>=35,"No debe",35-K16), A16="5lvl1",IF(L16>=35,"No debe",35-L16))} -> No debe
... A104: =IF(ISERROR(VLOOKUP(C104,'Caza lvl 1'!A:A,1,0)),"5lvl2","5lvl1") -> 5lvl2 | B104: =_xlfn.IFS(A104 = "5lvl2",IF(K104>=35,"Cumplio", "No cumplio"),A104 = "5lvl1",IF(L104>= 35,"Cumplio","No cumplio")) -> Cumplio | C104: 884346374 | D104: ZOOMBI3XX | E104: =SUM(F104:J104) -> 38 | F104: 0 | G104: 36 | H104: 0 | I104: 0 | J104: 2 | K104: =(H104*5)+(I104*9)+(J104*18)+G104 -> 72 | L104: =(G104*5)+(H104*15)+(I104*30)+(J104*70)+F104 -> 320 | M104: {=_xlfn.IFS(A104="5lvl2",IF(K104>=35,"No debe",35-K104), A104="5lvl1",IF(L104>=35,"No debe",35-L104))} -> No debe

Sheet Ranking Evento
A1: # | B1: IGG ID | C1: Nombre | D1: 10/05/2026 | E1: 17/05/2026 | F1: 24/05/2026 | G1: 46173 | I1: Total | J1: MAYO
A2: 1 | B2: 884346374 | C2: ZOOMBI3XX | D2: =IFERROR(VLOOKUP(B2,'10-05-2026'!C:K,9,0), 0) -> 162 | E2: =IFERROR(VLOOKUP(B2,'17-05-2026'!C:K,9,0), 0) -> 68 | F2: =IFERROR(VLOOKUP(B2,'24-05-2026'!C:K,9,0), 0) -> 61 | G2: =IFERROR(VLOOKUP(B2,Caza!C:K,9,0), 0) -> 72 | I2: =SUM(D2:H2) -> 363
A3: 2 | B3: 640955210 | C3: Valentin | D3: =IFERROR(VLOOKUP(B3,'10-05-2026'!C:K,9,0), 0) -> 73 | E3: =IFERROR(VLOOKUP(B3,'17-05-2026'!C:K,9,0), 0) -> 48 | F3: =IFERROR(VLOOKUP(B3,'24-05-2026'!C:K,9,0), 0) -> 36 | G3: =IFERROR(VLOOKUP(B3,Caza!C:K,9,0), 0) -> 183 | I3: =SUM(D3:H3) -> 340
A4: 3 | B4: 1023770253 | C4: K4K4SHI009 | D4: =IFERROR(VLOOKUP(B4,'10-05-2026'!C:K,9,0), 0) -> 71 | E4: =IFERROR(VLOOKUP(B4,'17-05-2026'!C:K,9,0), 0) -> 101 | F4: =IFERROR(VLOOKUP(B4,'24-05-2026'!C:K,9,0), 0) -> 63 | G4: =IFERROR(VLOOKUP(B4,Caza!C:K,9,0), 0) -> 71 | I4: =SUM(D4:H4) -> 306
A5: 4 | B5: 559847999 | C5: SoNy5 | D5: =IFERROR(VLOOKUP(B5,'10-05-2026'!C:K,9,0), 0) -> 86 | E5: =IFERROR(VLOOKUP(B5,'17-05-2026'!C:K,9,0), 0) -> 71 | F5: =IFERROR(VLOOKUP(B5,'24-05-2026'!C:K,9,0), 0) -> 81 | G5: =IFERROR(VLOOKUP(B5,Caza!C:K,9,0), 0) -> 67 | I5: =SUM(D5:H5) -> 305
A6: 5 | B6: 500920417 | C6: No Soy Bro | D6: =IFERROR(VLOOKUP(B6,'10-05-2026'!C:K,9,0), 0) -> 85 | E6: =IFERROR(VLOOKUP(B6,'17-05-2026'!C:K,9,0), 0) -> 85 | F6: =IFERROR(VLOOKUP(B6,'24-05-2026'!C:K,9,0), 0) -> 67 | G6: =IFERROR(VLOOKUP(B6,Caza!C:K,9,0), 0) -> 58 | I6: =SUM(D6:H6) -> 295
A7: 6 | B7: 1346964807 | C7: GokuBlack25 | D7: =IFERROR(VLOOKUP(B7,'10-05-2026'!C:K,9,0), 0) -> 49 | E7: =IFERROR(VLOOKUP(B7,'17-05-2026'!C:K,9,0), 0) -> 63 | F7: =IFERROR(VLOOKUP(B7,'24-05-2026'!C:K,9,0), 0) -> 57 | G7: =IFERROR(VLOOKUP(B7,Caza!C:K,9,0), 0) -> 113 | I7: =SUM(D7:H7) -> 282
A8: 7 | B8: 471968668 | C8: David051190 | D8: =IFERROR(VLOOKUP(B8,'10-05-2026'!C:K,9,0), 0) -> 90 | E8: =IFERROR(VLOOKUP(B8,'17-05-2026'!C:K,9,0), 0) -> 40 | F8: =IFERROR(VLOOKUP(B8,'24-05-2026'!C:K,9,0), 0) -> 71 | G8: =IFERROR(VLOOKUP(B8,Caza!C:K,9,0), 0) -> 79 | I8: =SUM(D8:H8) -> 280
A9: 8 | B9: 710619616 | C9: Vampyro3xxx | D9: =IFERROR(VLOOKUP(B9,'10-05-2026'!C:K,9,0), 0) -> 60 | E9: =IFERROR(VLOOKUP(B9,'17-05-2026'!C:K,9,0), 0) -> 72 | F9: =IFERROR(VLOOKUP(B9,'24-05-2026'!C:K,9,0), 0) -> 78 | G9: =IFERROR(VLOOKUP(B9,Caza!C:K,9,0), 0) -> 64 | I9: =SUM(D9:H9) -> 274
A10: 9 | B10: 689257712 | C10: Juanjojjp | D10: =IFERROR(VLOOKUP(B10,'10-05-2026'!C:K,9,0), 0) -> 66 | E10: =IFERROR(VLOOKUP(B10,'17-05-2026'!C:K,9,0), 0) -> 53 | F10: =IFERROR(VLOOKUP(B10,'24-05-2026'!C:K,9,0), 0) -> 92 | G10: =IFERROR(VLOOKUP(B10,Caza!C:K,9,0), 0) -> 57 | I10: =SUM(D10:H10) -> 268
A11: 10 | B11: 516441517 | C11: I GNACIO | D11: =IFERROR(VLOOKUP(B11,'10-05-2026'!C:K,9,0), 0) -> 67 | E11: =IFERROR(VLOOKUP(B11,'17-05-2026'!C:K,9,0), 0) -> 75 | F11: =IFERROR(VLOOKUP(B11,'24-05-2026'!C:K,9,0), 0) -> 54 | G11: =IFERROR(VLOOKUP(B11,Caza!C:K,9,0), 0) -> 67 | I11: =SUM(D11:H11) -> 263
A12: 11 | B12: 658843231 | C12: LifeToxic | D12: =IFERROR(VLOOKUP(B12,'10-05-2026'!C:K,9,0), 0) -> 90 | E12: =IFERROR(VLOOKUP(B12,'17-05-2026'!C:K,9,0), 0) -> 39 | F12: =IFERROR(VLOOKUP(B12,'24-05-2026'!C:K,9,0), 0) -> 70 | G12: =IFERROR(VLOOKUP(B12,Caza!C:K,9,0), 0) -> 45 | I12: =SUM(D12:H12) -> 244
A13: 12 | B13: 424972261 | C13: VALEP | D13: =IFERROR(VLOOKUP(B13,'10-05-2026'!C:K,9,0), 0) -> 71 | E13: =IFERROR(VLOOKUP(B13,'17-05-2026'!C:K,9,0), 0) -> 60 | F13: =IFERROR(VLOOKUP(B13,'24-05-2026'!C:K,9,0), 0) -> 53 | G13: =IFERROR(VLOOKUP(B13,Caza!C:K,9,0), 0) -> 49 | I13: =SUM(D13:H13) -> 233
... A101: 100 | B101: 1367372226 | C101: xtatux12 | D101: =IFERROR(VLOOKUP(B101,'10-05-2026'!C:K,9,0), 0) -> 3 | E101: =IFERROR(VLOOKUP(B101,'17-05-2026'!C:K,9,0), 0) -> 0 | F101: =IFERROR(VLOOKUP(B101,'24-05-2026'!C:K,9,0), 0) -> 0 | G101: =IFERROR(VLOOKUP(B101,Caza!C:K,9,0), 0) -> 0 | I101: =SUM(D101:H101) -> 3
A102: 101 | I102: =SUM(D102:H102) -> 0
A103: 104
A104: 105
A105: 106
A106: 107
A107: 108
A108: 109
A109: 110
A110: 111
A111: 112
A112: 113
A113: 114
A114: 115
A115: 116

Sheet Caza lvl 1
A1: IGGID | B1: NOMBRE
A2: 1367372226 | B2: XxtatuxX
A3: 1940642101 | B3: tetona
A4: 2057192192 | B4: NotLife2
A5: 2024927090 | B5: Atlas7770
A6: 2060348531 | B6: Hotspot 2
A7: 1338792213 | B7: El Guti26
A8: 677690297 | B8: FOODmil
A9: 600359996 | B9: lZvG Warasl
A10: 2115871936 | B10: Atlas55555
A11: 1390607562 | B11: criatura02
A12: 1931591455 | B12: XXGAELICOXX
A13: 1211883975 | B13: Online 16
... A17: 1067470462 | B17: OoChispitaoO

Sheet Avisos
A1: Cuota Diaria | B1: Status | C1: IGG ID | D1: Nombre | E1: Total Semanal | F1: Mob1 | G1: Mob2 | H1: Mob3 | I1: Mob4 | J1: Mob5 | K1: Puntos Nvl 2 | L1: Puntos Nvl 1 | M1: Debe | N1: Numero | O1: Puntos x cumplir | P1: Semana anterior | Q1: 46152 | R1: 46159 | S1: 46166
A2: 5lvl2 | B2: No cumplio | C2: 735092980 | D2: Gengar237 | E2: 5 | F2: 2 | G2: 2 | H2: 1 | I2: 0 | J2: 0 | K2: 7 | L2: 27 | M2: 28 | N2: =IFERROR(VLOOKUP(C2,Numeros!A:C,3,0),584121633097) -> 5212211427683 | O2: =SUM(M2,Q2,R2,S2)+35 -> 63 | P2: =COUNTIF('24-05-2026'!C:C, C2)>0 -> TRUE | Q2: 0 | R2: 0 | S2: 0
A3: 5lvl2 | B3: No cumplio | C3: 663429510 | D3: Megadiablo | E3: 19 | F3: 0 | G3: 16 | H3: 3 | I3: 0 | J3: 0 | K3: 31 | L3: 125 | M3: 4 | N3: =IFERROR(VLOOKUP(C3,Numeros!A:C,3,0),584121633097) -> 5214251085901 | O3: =SUM(M3,Q3,R3,S3)+35 -> 39 | P3: =COUNTIF('24-05-2026'!C:C, C3)>0 -> TRUE | Q3: 0 | R3: 0 | S3: 0
A4: 5lvl2 | B4: No cumplio | C4: 1040811175 | D4: SantiagoTb | E4: 10 | F4: 0 | G4: 4 | H4: 6 | I4: 0 | J4: 0 | K4: 34 | L4: 110 | M4: 1 | N4: =IFERROR(VLOOKUP(C4,Numeros!A:C,3,0),584121633097) -> 5219611812448 | O4: =SUM(M4,Q4,R4,S4)+35 -> 36 | P4: =COUNTIF('24-05-2026'!C:C, C4)>0 -> TRUE | Q4: 0 | R4: 0 | S4: 0

Sheet Numeros
A1: ID | B1: Nombre | C1: Numero
A2: 446013149 | B2: Abelino | C2: 51980377504
A3: 346561690 | B3: AGUIRRE1 | C3: 5493417036998
A4: 365438142 | B4: AGUIRRE1992 | C4: 5493417036998
A5: 315992503 | B5: ALMORO 00 | C5: 50685195956
A6: 339024723 | B6: Almoro01 | C6: 50685195956
A7: 355652066 | B7: Almoro02 | C7: 50685195956
A8: 2024927090 | B8: Atlas7770 | C8: 584121633097
A9: 642356966 | B9: Brandon 22 | C9: 5215584183166
A10: 1107848567 | B10: Deshuesado | C10: 5215584183166
A11: 940947273 | B11: Dpoolll TH | C11: 556596113286
A12: 967393022 | B12: DRACONIAN83 | C12: 56940442393
A13: 1535794879 | B13: DRAKEN13TH | C13: 5215523547766
... A85: 866932727 | B85: Destiny015 | C85: 50575406105

Sheet FDG
A1: Nombre | B1: Misiones completadas | C1: Misiones tomadas | D1: Puntos | F1: Fecha de Reporte
A2: X BAILEN X | B2: 16 | C2: 16 | D2: 4902 | F2: 25/05/2026 al 31/05/2026
A3: Nydan D | B3: 16 | C3: 16 | D3: 4671
A4: Megadiablo | B4: 16 | C4: 16 | D4: 4383
A5: Vampyro3xxx | B5: 16 | C5: 16 | D5: 4367
A6: GokuBlack25 | B6: 16 | C6: 16 | D6: 4234
A7: Atlas55555 | B7: 16 | C7: 16 | D7: 4182
A8: Inng3nN | B8: 16 | C8: 16 | D8: 4141
A9: JonyG2013 | B9: 16 | C9: 16 | D9: 4133
A10: Notlife 1 | B10: 16 | C10: 16 | D10: 4092
A11: Gastly237 | B11: 16 | C11: 16 | D11: 4079
A12: Th3BigB0ss | B12: 16 | C12: 16 | D12: 4066
A13: Maxi D | B13: 16 | C13: 16 | D13: 4060
A14: Barometrix | B14: 16 | C14: 16 | D14: 4033
... A95: Blurdomking | B95: 0 | C95: 0 | D95: 0

Sheet 10-05-2026
A1: Cuota Diaria | B1: Status | C1: IGG ID | D1: Nombre | E1: Total Semanal | F1: Total Mobs lvl 1 | G1: Total Mobs lvl 2 | H1: Total Mobs lvl 3 | I1: Total Mobs lvl 4 | J1: Total Mobs lvl 5 | M1: 04/05/2026 al 10/05/2026
D3: Total | E3: 2217 | F3: 134 | G3: 1745 | H3: 279 | I3: 29 | J3: 30
K4: Puntos Nvl 2 | L4: Puntos Nvl 1 | M4: Debe/No debe
A5: 5lvl2 | B5: No cumplio | C5: 2119238620 | D5: 1AVE FENIX2 | E5: 1 | F5: 1 | G5: 0 | H5: 0 | I5: 0 | J5: 0 | K5: 0 | L5: 1 | M5: 35
A6: 5lvl2 | B6: Cumplio | C6: 416845218 | D6: Abraracurcix | E6: 19 | F6: 0 | G6: 17 | H6: 0 | I6: 2 | J6: 0 | K6: 35 | L6: 145 | M6: No debe
A7: 5lvl2 | B7: No cumplio | C7: 597879167 | D7: ABSmadresYOU | E7: 5 | F7: 0 | G7: 3 | H7: 2 | I7: 0 | J7: 0 | K7: 13 | L7: 45 | M7: 22
A8: 5lvl2 | B8: Cumplio | C8: 346561690 | D8: AGUIRRE1 | E8: 18 | F8: 1 | G8: 10 | H8: 6 | I8: 1 | J8: 0 | K8: 49 | L8: 171 | M8: No debe
A9: 5lvl2 | B9: Cumplio | C9: 365438142 | D9: AGUIRRE1992 | E9: 12 | F9: 0 | G9: 4 | H9: 8 | I9: 0 | J9: 0 | K9: 44 | L9: 140 | M9: No debe
A10: 5lvl2 | B10: Cumplio | C10: 969689378 | D10: AlexRo1 | E10: 50 | F10: 0 | G10: 47 | H10: 3 | I10: 0 | J10: 0 | K10: 62 | L10: 280 | M10: No debe
A11: 5lvl2 | B11: No cumplio | C11: 0 | D11: Anonymous | E11: 0 | F11: 0 | G11: 0 | H11: 0 | I11: 0 | J11: 0 | K11: 0 | L11: 0 | M11: 35
A12: 5lvl2 | B12: Cumplio | C12: 326455645 | D12: Asterix I | E12: 50 | F12: 0 | G12: 50 | H12: 0 | I12: 0 | J12: 0 | K12: 50 | L12: 250 | M12: No debe
A13: 5lvl1 | B13: Cumplio | C13: 2115871936 | D13: Atlas55555 | E13: 19 | F13: 15 | G13: 4 | H13: 0 | I13: 0 | J13: 0 | K13: 4 | L13: 35 | M13: No debe
A14: 5lvl1 | B14: Cumplio | C14: 2024927090 | D14: Atlas7770 | E14: 7 | F14: 0 | G14: 7 | H14: 0 | I14: 0 | J14: 0 | K14: 7 | L14: 35 | M14: No debe
A15: 5lvl1 | B15: Cumplio | C15: 1483867967 | D15: badboys1 | E15: 5 | F15: 0 | G15: 4 | H15: 1 | I15: 0 | J15: 0 | K15: 9 | L15: 35 | M15: No debe
A16: 5lvl2 | B16: Cumplio | C16: 625607335 | D16: BadBoys4k | E16: 37 | F16: 0 | G16: 35 | H16: 2 | I16: 0 | J16: 0 | K16: 45 | L16: 205 | M16: No debe
A17: 5lvl2 | B17: Cumplio | C17: 357402771 | D17: Barometrix | E17: 23 | F17: 0 | G17: 20 | H17: 2 | I17: 1 | J17: 0 | K17: 39 | L17: 160 | M17: No debe
A18: 5lvl2 | B18: Cumplio | C18: 1041405085 | D18: BK Juanjo | E18: 25 | F18: 0 | G18: 22 | H18: 3 | I18: 0 | J18: 0 | K18: 37 | L18: 155 | M18: No debe
A19: 5lvl2 | B19: No cumplio | C19: 1693317344 | D19: BLACK Vzla | E19: 30 | F19: 0 | G19: 30 | H19: 0 | I19: 0 | J19: 0 | K19: 30 | L19: 150 | M19: 5
A20: 5lvl2 | B20: Cumplio | C20: 527890484 | D20: Blurdomking | E20: 52 | F20: 0 | G20: 37 | H20: 13 | I20: 2 | J20: 0 | K20: 120 | L20: 440 | M20: No debe
A21: 5lvl2 | B21: Cumplio | C21: 1036786251 | D21: cafecitofrio | E21: 11 | F21: 0 | G21: 5 | H21: 6 | I21: 0 | J21: 0 | K21: 35 | L21: 115 | M21: No debe
A22: 5lvl2 | B22: Cumplio | C22: 747071768 | D22: CHACHO 78 | E22: 41 | F22: 6 | G22: 35 | H22: 0 | I22: 0 | J22: 0 | K22: 35 | L22: 181 | M22: No debe
A23: 5lvl2 | B23: No cumplio | C23: 386453157 | D23: CONDEgatula | E23: 9 | F23: 0 | G23: 4 | H23: 5 | I23: 0 | J23: 0 | K23: 29 | L23: 95 | M23: 6
A24: 5lvl2 | B24: Cumplio | C24: 611721390 | D24: CrakSoder25 | E24: 17 | F24: 0 | G24: 13 | H24: 0 | I24: 0 | J24: 4 | K24: 85 | L24: 345 | M24: No debe
A25: 5lvl2 | B25: Cumplio | C25: 471968668 | D25: David051190 | E25: 41 | F25: 0 | G25: 34 | H25: 4 | I25: 2 | J25: 1 | K25: 90 | L25: 360 | M25: No debe
A26: 5lvl2 | B26: No cumplio | C26: 866932727 | D26: Destiny015 | E26: 26 | F26: 0 | G26: 25 | H26: 1 | I26: 0 | J26: 0 | K26: 30 | L26: 140 | M26: 5
A27: 5lvl2 | B27: No cumplio | C27: 412543735 | D27: ELFOSFO | E27: 5 | F27: 0 | G27: 0 | H27: 5 | I27: 0 | J27: 0 | K27: 25 | L27: 75 | M27: 10
A28: 5lvl2 | B28: Cumplio | C28: 723725687 | D28: FALCON221 | E28: 37 | F28: 0 | G28: 35 | H28: 0 | I28: 0 | J28: 2 | K28: 71 | L28: 315 | M28: No debe
A29: 5lvl2 | B29: No cumplio | C29: 1698596813 | D29: Gastly237 | E29: 30 | F29: 6 | G29: 24 | H29: 0 | I29: 0 | J29: 0 | K29: 24 | L29: 126 | M29: 11
A30: 5lvl2 | B30: No cumplio | C30: 735092980 | D30: Gengar237 | E30: 8 | F30: 1 | G30: 5 | H30: 2 | I30: 0 | J30: 0 | K30: 15 | L30: 56 | M30: 20
A31: 5lvl2 | B31: Cumplio | C31: 1346964807 | D31: GokuBlack25 | E31: 29 | F31: 0 | G31: 24 | H31: 5 | I31: 0 | J31: 0 | K31: 49 | L31: 195 | M31: No debe
A32: 5lvl2 | B32: Cumplio | C32: 1529804845 | D32: GokuBlack26 | E32: 26 | F32: 0 | G32: 20 | H32: 6 | I32: 0 | J32: 0 | K32: 50 | L32: 190 | M32: No debe
A33: 5lvl1 | B33: Cumplio | C33: 2060348531 | D33: Hotspot 2 | E33: 14 | F33: 8 | G33: 6 | H33: 0 | I33: 0 | J33: 0 | K33: 6 | L33: 38 | M33: No debe
A34: 5lvl2 | B34: Cumplio | C34: 516441517 | D34: I GNACIO | E34: 29 | F34: 0 | G34: 26 | H34: 1 | I34: 0 | J34: 2 | K34: 67 | L34: 285 | M34: No debe
A35: 5lvl2 | B35: Cumplio | C35: 1041170254 | D35: il pegaso | E35: 9 | F35: 0 | G35: 0 | H35: 9 | I35: 0 | J35: 0 | K35: 45 | L35: 135 | M35: No debe
A36: 5lvl2 | B36: Cumplio | C36: 334846462 | D36: Inng3nN | E36: 47 | F36: 0 | G36: 41 | H36: 4 | I36: 0 | J36: 2 | K36: 97 | L36: 405 | M36: No debe
A37: 5lvl2 | B37: Cumplio | C37: 1092680272 | D37: ins4n3 TH | E37: 26 | F37: 0 | G37: 22 | H37: 2 | I37: 2 | J37: 0 | K37: 50 | L37: 200 | M37: No debe
A38: 5lvl2 | B38: Cumplio | C38: 689257712 | D38: Juanjojjp | E38: 15 | F38: 1 | G38: 1 | H38: 13 | I38: 0 | J38: 0 | K38: 66 | L38: 201 | M38: No debe
A39: 5lvl2 | B39: Cumplio | C39: 1023770253 | D39: K4K4SHI009 | E39: 11 | F39: 0 | G39: 2 | H39: 3 | I39: 6 | J39: 0 | K39: 71 | L39: 235 | M39: No debe
A40: 5lvl2 | B40: Cumplio | C40: 1041184896 | D40: KeoIII1 | E40: 27 | F40: 0 | G40: 22 | H40: 5 | I40: 0 | J40: 0 | K40: 47 | L40: 185 | M40: No debe
A41: 5lvl2 | B41: No cumplio | C41: 613063847 | D41: M3GA6 | E41: 0 | F41: 0 | G41: 0 | H41: 0 | I41: 0 | J41: 0 | K41: 0 | L41: 0 | M41: 35
...

Sheet 17-05-2026
A1: Cuota Diaria | B1: Status | C1: IGG ID | D1: Nombre | E1: Total Semanal | F1: Total Mobs lvl 1 | G1: Total Mobs lvl 2 | H1: Total Mobs lvl 3 | I1: Total Mobs lvl 4 | J1: Total Mobs lvl 5 | M1: 11/05/2026 al 17/05/2026
D3: Total | E3: 2059 | F3: 74 | G3: 1596 | H3: 356 | I3: 32 | J3: 1
K4: Puntos Nvl 2 | L4: Puntos Nvl 1 | M4: Debe/No debe
A5: 5lvl2 | B5: Cumplio | C5: 1023770253 | D5: K4K4SHI009 | E5: 17 | F5: 0 | G5: 0 | H5: 13 | I5: 4 | J5: 0 | K5: 101 | L5: 315 | M5: No debe
A6: 5lvl2 | B6: Cumplio | C6: 500920417 | D6: No Soy Bro | E6: 29 | F6: 0 | G6: 15 | H6: 14 | I6: 0 | J6: 0 | K6: 85 | L6: 285 | M6: No debe
A7: 5lvl2 | B7: Cumplio | C7: 516441517 | D7: I GNACIO | E7: 23 | F7: 0 | G7: 10 | H7: 13 | I7: 0 | J7: 0 | K7: 75 | L7: 245 | M7: No debe
A8: 5lvl2 | B8: Cumplio | C8: 1529804845 | D8: GokuBlack26 | E8: 20 | F8: 0 | G8: 7 | H8: 13 | I8: 0 | J8: 0 | K8: 72 | L8: 230 | M8: No debe
A9: 5lvl2 | B9: Cumplio | C9: 710619616 | D9: Vampyro3xxx | E9: 12 | F9: 0 | G9: 1 | H9: 7 | I9: 4 | J9: 0 | K9: 72 | L9: 230 | M9: No debe
A10: 5lvl2 | B10: Cumplio | C10: 559847999 | D10: SoNy5 | E10: 35 | F10: 0 | G10: 26 | H10: 9 | I10: 0 | J10: 0 | K10: 71 | L10: 265 | M10: No debe
A11: 5lvl2 | B11: Cumplio | C11: 663429510 | D11: Megadiablo | E11: 32 | F11: 0 | G11: 26 | H11: 5 | I11: 0 | J11: 1 | K11: 69 | L11: 275 | M11: No debe
A12: 5lvl2 | B12: Cumplio | C12: 1092680272 | D12: ins4n3 TH | E12: 28 | F12: 0 | G12: 21 | H12: 4 | I12: 3 | J12: 0 | K12: 68 | L12: 255 | M12: No debe
A13: 5lvl2 | B13: Cumplio | C13: 884346374 | D13: ZOOMBI3XX | E13: 40 | F13: 0 | G13: 33 | H13: 7 | I13: 0 | J13: 0 | K13: 68 | L13: 270 | M13: No debe
A14: 5lvl2 | B14: Cumplio | C14: 1346964807 | D14: GokuBlack25 | E14: 29 | F14: 2 | G14: 18 | H14: 9 | I14: 0 | J14: 0 | K14: 63 | L14: 227 | M14: No debe
A15: 5lvl2 | B15: Cumplio | C15: 376342700 | D15: NoSoyWey | E15: 21 | F15: 0 | G15: 11 | H15: 10 | I15: 0 | J15: 0 | K15: 61 | L15: 205 | M15: No debe
A16: 5lvl2 | B16: Cumplio | C16: 527890484 | D16: Blurdomking | E16: 37 | F16: 0 | G16: 31 | H16: 6 | I16: 0 | J16: 0 | K16: 61 | L16: 245 | M16: No debe
... A75: 5lvl2 | B75: Cumplio | C75: 927459756 | D75: Vegueta blu | E75: 11 | F75: 0 | G75: 6 | H75: 4 | I75: 1 | J75: 0 | K75: 35 | L75: 120 | M75: No debe
A76: 5lvl2 | B76: No cumplio | C76: 1040811175 | D76: SantiagoTb | E76: 22 | F76: 0 | G76: 19 | H76: 3 | I76: 0 | J76: 0 | K76: 34 | L76: 140 | M76: 1
A77: 5lvl2 | B77: No cumplio | C77: 1769834648 | D77: Vegueta 69 | E77: 30 | F77: 0 | G77: 30 | H77: 0 | I77: 0 | J77: 0 | K77: 30 | L77: 150 | M77: 5
A78: 5lvl1 | B78: Cumplio | C78: 1264043363 | D78: xavy3r | E78: 6 | F78: 0 | G78: 0 | H78: 6 | I78: 0 | J78: 0 | K78: 30 | L78: 90 | M78: No debe
A79: 5lvl2 | B79: No cumplio | C79: 852051372 | D79: mini culichi | E79: 15 | F79: 0 | G79: 12 | H79: 3 | I79: 0 | J79: 0 | K79: 27 | L79: 105 | M79: 8
A80: 5lvl2 | B80: No cumplio | C80: 1279827382 | D80: PESADOS12 | E80: 10 | F80: 0 | G80: 6 | H80: 4 | I80: 0 | J80: 0 | K80: 26 | L80: 90 | M80: 9
A81: 5lvl2 | B81: No cumplio | C81: 526144427 | D81: sargent01 | E81: 8 | F81: 0 | G81: 4 | H81: 4 | I81: 0 | J81: 0 | K81: 24 | L81: 80 | M81: 11
A82: 5lvl2 | B82: No cumplio | C82: 1268693750 | D82: Vzla Free | E82: 19 | F82: 0 | G82: 18 | H82: 1 | I82: 0 | J82: 0 | K82: 23 | L82: 105 | M82: 12
A83: 5lvl2 | B83: No cumplio | C83: 386453157 | D83: CONDEGATUDHA | E83: 6 | F83: 0 | G83: 2 | H83: 4 | I83: 0 | J83: 0 | K83: 22 | L83: 70 | M83: 13
A84: 5lvl2 | B84: No cumplio | C84: 1041187189 | D84: RODRIGUEZ 12 | E84: 4 | F84: 0 | G84: 1 | H84: 2 | I84: 1 | J84: 0 | K84: 20 | L84: 65 | M84: 15
A85: 5lvl1 | B85: Cumplio | C85: 1067470462 | D85: OoChispitaoO | E85: 19 | F85: 0 | G85: 19 | H85: 0 | I85: 0 | J85: 0 | K85: 19 | L85: 95 | M85: No debe
A86: 5lvl2 | B86: No cumplio | C86: 1727138266 | D86: xRudius | E86: 4 | F86: 0 | G86: 1 | H86: 3 | I86: 0 | J86: 0 | K86: 16 | L86: 50 | M86: 19
A87: 5lvl1 | B87: Cumplio | C87: 1483867967 | D87: badboys1 | E87: 4 | F87: 0 | G87: 2 | H87: 2 | I87: 0 | J87: 0 | K87: 12 | L87: 40 | M87: No debe
A88: 5lvl2 | B88: No cumplio | C88: 422938512 | D88: Pactroclidha | E88: 4 | F88: 0 | G88: 2 | H88: 2 | I88: 0 | J88: 0 | K88: 12 | L88: 40 | M88: 23
A89: 5lvl2 | B89: No cumplio | C89: 952505208 | D89: OZUNA01 | E89: 9 | F89: 0 | G89: 9 | H89: 0 | I89: 0 | J89: 0 | K89: 9 | L89: 45 | M89: 26
A90: 5lvl1 | B90: Cumplio | C90: 1931591455 | D90: XXGAELICOXX | E90: 5 | F90: 0 | G90: 4 | H90: 1 | I90: 0 | J90: 0 | K90: 9 | L90: 35 | M90: No debe
A91: 5lvl1 | B91: Cumplio | C91: 2024927090 | D91: Atlas7770 | E91: 8 | F91: 0 | G91: 8 | H91: 0 | I91: 0 | J91: 0 | K91: 8 | L91: 40 | M91: No debe
A92: 5lvl1 | B92: Cumplio | C92: 2057192192 | D92: NotLife2 | E92: 14 | F92: 11 | G92: 2 | H92: 1 | I92: 0 | J92: 0 | K92: 7 | L92: 36 | M92: No debe
A93: 5lvl2 | B93: No cumplio | C93: 689818698 | D93: EmpAnadita1 | E93: 7 | F93: 0 | G93: 7 | H93: 0 | I93: 0 | J93: 0 | K93: 7 | L93: 35 | M93: 28
A94: 5lvl1 | B94: Cumplio | C94: 2060348531 | D94: Hotspot 2 | E94: 13 | F94: 7 | G94: 6 | H94: 0 | I94: 0 | J94: 0 | K94: 6 | L94: 37 | M94: No debe
A95: 5lvl2 | B95: No cumplio | C95: 319651861 | D95: granjita88 | E95: 6 | F95: 0 | G95: 6 | H95: 0 | I95: 0 | J95: 0 | K95: 6 | L95: 30 | M95: 29
A96: 5lvl2 | B96: No cumplio | C96: 582104628 | D96: JonyG2013 | E96: 6 | F96: 0 | G96: 6 | H96: 0 | I96: 0 | J96: 0 | K96: 6 | L96: 30 | M96: 29
A97: 5lvl2 | B97: No cumplio | C97: 1693317344 | D97: BLACK Vzla | E97: 6 | F97: 0 | G97: 6 | H97: 0 | I97: 0 | J97: 0 | K97: 6 | L97: 30 | M97: 29
A98: 5lvl2 | B98: No cumplio | C98: 440323888 | D98: NEW TOP | E98: 2 | F98: 0 | G98: 1 | H98: 1 | I98: 0 | J98: 0 | K98: 6 | L98: 20 | M98: 29
A99: 5lvl1 | B99: Cumplio | C99: 2115871936 | D99: Atlas55555 | E99: 16 | F99: 11 | G99: 5 | H99: 0 | I99: 0 | J99: 0 | K99: 5 | L99: 36 | M99: No debe
...

Sheet 24-05-2026
A1: Cuota Diaria | B1: Status | C1: IGG ID | D1: Nombre | E1: Total Semanal | F1: Total Mobs lvl 1 | G1: Total Mobs lvl 2 | H1: Total Mobs lvl 3 | I1: Total Mobs lvl 4 | J1: Total Mobs lvl 5 | M1: 18/05/2026 al 24/05/2026
D3: Total | E3: 2359 | F3: 127 | G3: 1798 | H3: 388 | I3: 44 | J3: 2
K4: Puntos Nvl 2 | L4: Puntos Nvl 1 | M4: Debe/No debe
A5: 5lvl2 | B5: Cumplio | C5: 416845218 | D5: Abraracurcix | E5: 11 | F5: 0 | G5: 7 | H5: 2 | I5: 2 | J5: 0 | K5: 35 | L5: 125 | M5: No debe
A6: 5lvl2 | B6: Cumplio | C6: 346561690 | D6: AGUIRRE1 | E6: 14 | F6: 0 | G6: 9 | H6: 4 | I6: 1 | J6: 0 | K6: 38 | L6: 135 | M6: No debe
A7: 5lvl2 | B7: Cumplio | C7: 365438142 | D7: AGUIRRE1992 | E7: 6 | F7: 0 | G7: 0 | H7: 4 | I7: 2 | J7: 0 | K7: 38 | L7: 120 | M7: No debe
A8: 5lvl2 | B8: Cumplio | C8: 0 | D8: Anonymous | E8: 12 | F8: 0 | G8: 3 | H8: 4 | I8: 5 | J8: 0 | K8: 68 | L8: 225 | M8: No debe
A9: 5lvl2 | B9: No cumplio | C9: 736031655 | D9: aquilucho | E9: 1 | F9: 0 | G9: 0 | H9: 1 | I9: 0 | J9: 0 | K9: 5 | L9: 15 | M9: 30
A10: 5lvl2 | B10: Cumplio | C10: 326455645 | D10: Asterix I | E10: 35 | F10: 0 | G10: 35 | H10: 0 | I10: 0 | J10: 0 | K10: 35 | L10: 175 | M10: No debe
A11: 5lvl1 | B11: Cumplio | C11: 2115871936 | D11: Atlas55555 | E11: 20 | F11: 16 | G11: 4 | H11: 0 | I11: 0 | J11: 0 | K11: 4 | L11: 36 | M11: No debe
A12: 5lvl1 | B12: Cumplio | C12: 2024927090 | D12: Atlas7770 | E12: 16 | F12: 6 | G12: 9 | H12: 1 | I12: 0 | J12: 0 | K12: 14 | L12: 66 | M12: No debe
A13: 5lvl1 | B13: Cumplio | C13: 1483867967 | D13: badboys1 | E13: 7 | F13: 0 | G13: 7 | H13: 0 | I13: 0 | J13: 0 | K13: 7 | L13: 35 | M13: No debe
A14: 5lvl2 | B14: Cumplio | C14: 625607335 | D14: BadBoys4k | E14: 31 | F14: 0 | G14: 30 | H14: 0 | I14: 0 | J14: 1 | K14: 48 | L14: 220 | M14: No debe
A15: 5lvl2 | B15: Cumplio | C15: 357402771 | D15: Barometrix | E15: 21 | F15: 0 | G15: 17 | H15: 4 | I15: 0 | J15: 0 | K15: 37 | L15: 145 | M15: No debe
A16: 5lvl2 | B16: Cumplio | C16: 1041405085 | D16: BK Juanjo | E16: 27 | F16: 0 | G16: 25 | H16: 2 | I16: 0 | J16: 0 | K16: 35 | L16: 155 | M16: No debe
A17: 5lvl2 | B17: Cumplio | C17: 1036786251 | D17: cafecitofrio | E17: 14 | F17: 0 | G17: 7 | H17: 7 | I17: 0 | J17: 0 | K17: 42 | L17: 140 | M17: No debe
A18: 5lvl2 | B18: Cumplio | C18: 747071768 | D18: CHACHO 78 | E18: 19 | F18: 0 | G18: 15 | H18: 4 | I18: 0 | J18: 0 | K18: 35 | L18: 135 | M18: No debe
A19: 5lvl2 | B19: Cumplio | C19: 386453157 | D19: CONDEGATUDHA | E19: 14 | F19: 0 | G19: 5 | H19: 9 | I19: 0 | J19: 0 | K19: 50 | L19: 160 | M19: No debe
A20: 5lvl2 | B20: Cumplio | C20: 611721390 | D20: CrakSoder25 | E20: 35 | F20: 0 | G20: 35 | H20: 0 | I20: 0 | J20: 0 | K20: 35 | L20: 175 | M20: No debe
A21: 5lvl2 | B21: Cumplio | C21: 881905775 | D21: DANTEE666 | E21: 29 | F21: 0 | G21: 22 | H21: 7 | I21: 0 | J21: 0 | K21: 57 | L21: 215 | M21: No debe
A22: 5lvl2 | B22: Cumplio | C22: 471968668 | D22: David051190 | E22: 39 | F22: 0 | G22: 34 | H22: 2 | I22: 3 | J22: 0 | K22: 71 | L22: 290 | M22: No debe
A23: 5lvl2 | B23: No cumplio | C23: 866932727 | D23: Destiny015 | E23: 8 | F23: 0 | G23: 6 | H23: 2 | I23: 0 | J23: 0 | K23: 16 | L23: 60 | M23: 19
A24: 5lvl2 | B24: No cumplio | C24: 412543735 | D24: ELFOSFO | E24: 6 | F24: 0 | G24: 1 | H24: 5 | I24: 0 | J24: 0 | K24: 26 | L24: 80 | M24: 9
A25: 5lvl2 | B25: No cumplio | C25: 689818698 | D25: EmpAnadita1 | E25: 19 | F25: 0 | G25: 17 | H25: 2 | I25: 0 | J25: 0 | K25: 27 | L25: 115 | M25: 8
A26: 5lvl2 | B26: No cumplio | C26: 1401689756 | D26: Empanadita2 | E26: 26 | F26: 0 | G26: 26 | H26: 0 | I26: 0 | J26: 0 | K26: 26 | L26: 130 | M26: 9
A27: 5lvl2 | B27: Cumplio | C27: 723725687 | D27: FALCON221 | E27: 43 | F27: 0 | G27: 41 | H27: 2 | I27: 0 | J27: 0 | K27: 51 | L27: 235 | M27: No debe
A28: 5lvl2 | B28: Cumplio | C28: 1698596813 | D28: Gastly237 | E28: 31 | F28: 0 | G28: 30 | H28: 1 | I28: 0 | J28: 0 | K28: 35 | L28: 165 | M28: No debe
A29: 5lvl2 | B29: Cumplio | C29: 735092980 | D29: Gengar237 | E29: 16 | F29: 0 | G29: 11 | H29: 5 | I29: 0 | J29: 0 | K29: 36 | L29: 130 | M29: No debe
A30: 5lvl2 | B30: Cumplio | C30: 1346964807 | D30: GokuBlack25 | E30: 37 | F30: 0 | G30: 32 | H30: 5 | I30: 0 | J30: 0 | K30: 57 | L30: 235 | M30: No debe
A31: 5lvl2 | B31: Cumplio | C31: 1529804845 | D31: GokuBlack26 | E31: 30 | F31: 0 | G31: 24 | H31: 6 | I31: 0 | J31: 0 | K31: 54 | L31: 210 | M31: No debe
A32: 5lvl2 | B32: No cumplio | C32: 319651861 | D32: granjita88 | E32: 9 | F32: 0 | G32: 7 | H32: 2 | I32: 0 | J32: 0 | K32: 17 | L32: 65 | M32: 18
A33: 5lvl2 | B33: Cumplio | C33: 817775064 | D33: Hades 04 | E33: 23 | F33: 0 | G33: 17 | H33: 3 | I33: 3 | J33: 0 | K33: 59 | L33: 220 | M33: No debe
A34: 5lvl1 | B34: Cumplio | C34: 2060348531 | D34: Hotspot 2 | E34: 16 | F34: 11 | G34: 5 | H34: 0 | I34: 0 | J34: 0 | K34: 5 | L34: 36 | M34: No debe
A35: 5lvl2 | B35: Cumplio | C35: 516441517 | D35: I GNACIO | E35: 34 | F35: 0 | G35: 31 | H35: 1 | I35: 2 | J35: 0 | K35: 54 | L35: 230 | M35: No debe
A36: 5lvl2 | B36: Cumplio | C36: 1041170254 | D36: il pegaso | E36: 7 | F36: 0 | G36: 0 | H36: 7 | I36: 0 | J36: 0 | K36: 35 | L36: 105 | M36: No debe
A37: 5lvl2 | B37: Cumplio | C37: 334846462 | D37: Inng3nN | E37: 26 | F37: 0 | G37: 22 | H37: 3 | I37: 1 | J37: 0 | K37: 46 | L37: 185 | M37: No debe
A38: 5lvl2 | B38: Cumplio | C38: 1092680272 | D38: ins4n3 TH | E38: 26 | F38: 0 | G38: 18 | H38: 7 | I38: 1 | J38: 0 | K38: 62 | L38: 225 | M38: No debe
A39: 5lvl2 | B39: No cumplio | C39: 545681080 | D39: JmanuR | E39: 8 | F39: 0 | G39: 7 | H39: 1 | I39: 0 | J39: 0 | K39: 12 | L39: 50 | M39: 23
A40: 5lvl2 | B40: Cumplio | C40: 582104628 | D40: JonyG2013 | E40: 27 | F40: 0 | G40: 25 | H40: 2 | I40: 0 | J40: 0 | K40: 35 | L40: 155 | M40: No debe
A41: 5lvl2 | B41: Cumplio | C41: 689257712 | D41: Juanjojjp | E41: 20 | F41: 0 | G41: 2 | H41: 18 | I41: 0 | J41: 0 | K41: 92 | L41: 280 | M41: No debe
...
